<sdf version='1.7'>
  <world name='default'>
    <light name='sun' type='directional'>
      <cast_shadows>1</cast_shadows>
      <pose>0 0 10 0 -0 0</pose>
      <diffuse>0.8 0.8 0.8 1</diffuse>
      <specular>0.2 0.2 0.2 1</specular>
      <attenuation>
        <range>1000</range>
        <constant>0.9</constant>
        <linear>0.01</linear>
        <quadratic>0.001</quadratic>
      </attenuation>
      <direction>-0.5 0.1 -0.9</direction>
      <spot>
        <inner_angle>0</inner_angle>
        <outer_angle>0</outer_angle>
        <falloff>0</falloff>
      </spot>
    </light>
    <gravity>0 0 -9.8</gravity>
    <magnetic_field>6e-06 2.3e-05 -4.2e-05</magnetic_field>
    <atmosphere type='adiabatic'/>
    <physics type='ode'>
      <max_step_size>0.001</max_step_size>
      <real_time_factor>1</real_time_factor>
      <real_time_update_rate>1000</real_time_update_rate>
    </physics>
    <scene>
      <ambient>0.4 0.4 0.4 1</ambient>
      <background>0.7 0.7 0.7 1</background>
      <shadows>1</shadows>
    </scene>
    <audio>
      <device>default</device>
    </audio>
    <wind/>
    <spherical_coordinates>
      <surface_model>EARTH_WGS84</surface_model>
      <latitude_deg>0</latitude_deg>
      <longitude_deg>0</longitude_deg>
      <elevation>0</elevation>
      <heading_deg>0</heading_deg>
    </spherical_coordinates>
    <model name='my_ground_plane'>
      <static>1</static>
      <link name='link'>
        <collision name='collision'>
          <geometry>
            <plane>
              <normal>0 0 1</normal>
              <size>50 50</size>
            </plane>
          </geometry>
          <surface>
            <friction>
              <ode>
                <mu>100</mu>
                <mu2>50</mu2>
              </ode>
              <torsional>
                <ode/>
              </torsional>
            </friction>
            <contact>
              <ode/>
            </contact>
            <bounce/>
          </surface>
          <max_contacts>10</max_contacts>
        </collision>
        <visual name='visual'>
          <cast_shadows>0</cast_shadows>
          <geometry>
            <plane>
              <normal>0 0 1</normal>
              <size>50 50</size>
            </plane>
          </geometry>
          <material>
            <script>
              <uri>/home/arc/Documents/GitHub/IGVC-Robot/GazeboR1/GroundPlane/groundplane.material</uri>
              <name>MyGroundPlane/Image</name>
            </script>
          </material>
        </visual>
        <self_collide>0</self_collide>
        <enable_wind>0</enable_wind>
        <kinematic>0</kinematic>
      </link>
      <pose>-0.007726 -0.007727 0 0 -0 0</pose>
    </model>
    <model name='HitBox'>
      <link name='Frame'>
        <inertial>
          <pose>0.326466 0.45024 0.186919 0 -0 0</pose>
          <mass>35.592</mass>
          <inertia>
            <ixx>550.906</ixx>
            <ixy>0</ixy>
            <ixz>0</ixz>
            <iyy>656.955</iyy>
            <iyz>0</iyz>
            <izz>317.173</izz>
          </inertia>
        </inertial>
        <collision name='Frame_collision'>
          <pose>0 0 0.04826 0 -0 0</pose>
          <geometry>
            <mesh>
              <scale>1 1 1</scale>
              <uri>/home/arc/Documents/GitHub/IGVC-Robot/GazeboR1/WorkingRobot/Frame.STL</uri>
            </mesh>
          </geometry>
          <max_contacts>10</max_contacts>
          <surface>
            <contact>
              <ode/>
            </contact>
            <bounce/>
            <friction>
              <torsional>
                <ode/>
              </torsional>
              <ode/>
            </friction>
          </surface>
        </collision>
        <visual name='Frame_visual'>
          <pose>0 0 0.04826 0 -0 3.14159</pose>
          <geometry>
            <mesh>
              <scale>1 1 1</scale>
              <uri>/home/arc/Documents/GitHub/IGVC-Robot/GazeboR1/WorkingRobot/Frame_Detailed.STL</uri>
            </mesh>
          </geometry>
        </visual>
        <self_collide>0</self_collide>
        <enable_wind>0</enable_wind>
        <kinematic>0</kinematic>
      </link>
      <joint name='BL_Axel' type='revolute'>
        <pose relative_to='Frame'>-0.012938 0.1062 0.099568 1.5708 -0 0</pose>
        <parent>Frame</parent>
        <child>BL_Wheel</child>
        <axis>
          <xyz>0 0 0</xyz>
          <limit>
            <lower>-1e+16</lower>
            <upper>1e+16</upper>
          </limit>
          <dynamics>
            <spring_reference>0</spring_reference>
            <spring_stiffness>0</spring_stiffness>
          </dynamics>
        </axis>
      </joint>
      <link name='BL_Wheel'>
        <pose relative_to='BL_Axel'>0 0 0 0 -0 3.14159</pose>
        <inertial>
          <pose>0 0 0 0 -0 0</pose>
          <mass>1</mass>
          <inertia>
            <ixx>0.006867</ixx>
            <ixy>-1.0588e-20</ixy>
            <ixz>1.9852e-20</ixz>
            <iyy>0.0037033</iyy>
            <iyz>-5.9778e-36</iyz>
            <izz>0.0037033</izz>
          </inertia>
        </inertial>
        <collision name='BL_Wheel_collision'>
          <pose>0 0 0 0 -0 0</pose>
          <geometry>
            <mesh>
              <scale>1 1 1</scale>
              <uri>/home/arc/Documents/GitHub/IGVC-Robot/GazeboR1/WorkingRobot/Wheel_Detailed.STL</uri>
            </mesh>
          </geometry>
          <max_contacts>10</max_contacts>
          <surface>
            <contact>
              <ode/>
            </contact>
            <bounce/>
            <friction>
              <torsional>
                <ode/>
              </torsional>
              <ode/>
            </friction>
          </surface>
        </collision>
        <visual name='BL_Wheel_visual'>
          <pose>0 0 0 0 -0 0</pose>
          <geometry>
            <mesh>
              <scale>1 1 1</scale>
              <uri>/home/arc/Documents/GitHub/IGVC-Robot/GazeboR1/WorkingRobot/Wheel_Detailed.STL</uri>
            </mesh>
          </geometry>
        </visual>
        <self_collide>0</self_collide>
        <enable_wind>0</enable_wind>
        <kinematic>0</kinematic>
      </link>
      <joint name='BR_Axel' type='revolute'>
        <pose relative_to='Frame'>0.67333 0.1062 0.099568 1.5708 -0 0</pose>
        <parent>Frame</parent>
        <child>BR_Wheel</child>
        <axis>
          <xyz>0 0 0</xyz>
          <limit>
            <lower>-1e+16</lower>
            <upper>1e+16</upper>
          </limit>
          <dynamics>
            <spring_reference>0</spring_reference>
            <spring_stiffness>0</spring_stiffness>
          </dynamics>
        </axis>
      </joint>
      <link name='BR_Wheel'>
        <pose relative_to='BR_Axel'>0 0 0 0 -0 0</pose>
        <inertial>
          <pose>0.024308 0 0 0 -0 0</pose>
          <mass>1</mass>
          <inertia>
            <ixx>0.006867</ixx>
            <ixy>-1.0588e-20</ixy>
            <ixz>6.6174e-21</ixz>
            <iyy>0.0037033</iyy>
            <iyz>-5.9778e-36</iyz>
            <izz>0.0037033</izz>
          </inertia>
        </inertial>
        <collision name='BR_Wheel_collision'>
          <pose>0 0 0 0 -0 0</pose>
          <geometry>
            <mesh>
              <scale>1 1 1</scale>
              <uri>/home/arc/Documents/GitHub/IGVC-Robot/GazeboR1/WorkingRobot/Wheel_Detailed.STL</uri>
            </mesh>
          </geometry>
          <max_contacts>10</max_contacts>
          <surface>
            <contact>
              <ode/>
            </contact>
            <bounce/>
            <friction>
              <torsional>
                <ode/>
              </torsional>
              <ode/>
            </friction>
          </surface>
        </collision>
        <visual name='BR_Wheel_visual'>
          <pose>0 0 0 0 -0 0</pose>
          <geometry>
            <mesh>
              <scale>1 1 1</scale>
              <uri>/home/arc/Documents/GitHub/IGVC-Robot/GazeboR1/WorkingRobot/Wheel_Detailed.STL</uri>
            </mesh>
          </geometry>
        </visual>
        <self_collide>0</self_collide>
        <enable_wind>0</enable_wind>
        <kinematic>0</kinematic>
      </link>
      <joint name='FL_Axel' type='revolute'>
        <pose relative_to='Frame'>-0.012938 0.8082 0.099568 1.5708 -0 0</pose>
        <parent>Frame</parent>
        <child>FL_Wheel</child>
        <axis>
          <xyz>0 0 0</xyz>
          <limit>
            <lower>-1e+16</lower>
            <upper>1e+16</upper>
          </limit>
          <dynamics>
            <spring_reference>0</spring_reference>
            <spring_stiffness>0</spring_stiffness>
          </dynamics>
        </axis>
      </joint>
      <link name='FL_Wheel'>
        <pose relative_to='FL_Axel'>0 0 0 0 -0 3.14159</pose>
        <inertial>
          <pose>0.024308 0 0 0 -0 0</pose>
          <mass>1</mass>
          <inertia>
            <ixx>0.006867</ixx>
            <ixy>-1.0588e-20</ixy>
            <ixz>1.9852e-20</ixz>
            <iyy>0.0037033</iyy>
            <iyz>-5.9778e-36</iyz>
            <izz>0.0037033</izz>
          </inertia>
        </inertial>
        <collision name='FL_Wheel_collision'>
          <pose>0 0 0 0 -0 0</pose>
          <geometry>
            <mesh>
              <scale>1 1 1</scale>
              <uri>/home/arc/Documents/GitHub/IGVC-Robot/GazeboR1/WorkingRobot/Wheel_Detailed.STL</uri>
            </mesh>
          </geometry>
          <max_contacts>10</max_contacts>
          <surface>
            <contact>
              <ode/>
            </contact>
            <bounce/>
            <friction>
              <torsional>
                <ode/>
              </torsional>
              <ode/>
            </friction>
          </surface>
        </collision>
        <visual name='FL_Wheel_visual'>
          <pose>0 0 0 0 -0 0</pose>
          <geometry>
            <mesh>
              <scale>1 1 1</scale>
              <uri>/home/arc/Documents/GitHub/IGVC-Robot/GazeboR1/WorkingRobot/Wheel_Detailed.STL</uri>
            </mesh>
          </geometry>
        </visual>
        <self_collide>0</self_collide>
        <enable_wind>0</enable_wind>
        <kinematic>0</kinematic>
      </link>
      <joint name='FR_Axel' type='revolute'>
        <pose relative_to='Frame'>0.67333 0.8082 0.099568 1.5708 -0 0</pose>
        <parent>Frame</parent>
        <child>FR_Wheel</child>
        <axis>
          <xyz>0 0 0</xyz>
          <limit>
            <lower>-1e+16</lower>
            <upper>1e+16</upper>
          </limit>
          <dynamics>
            <spring_reference>0</spring_reference>
            <spring_stiffness>0</spring_stiffness>
          </dynamics>
        </axis>
      </joint>
      <link name='FR_Wheel'>
        <pose relative_to='FR_Axel'>0 0 0 0 -0 0</pose>
        <inertial>
          <pose>0.024308 0 0 0 -0 0</pose>
          <mass>1</mass>
          <inertia>
            <ixx>0.006867</ixx>
            <ixy>-1.0588e-20</ixy>
            <ixz>6.6174e-21</ixz>
            <iyy>0.0037033</iyy>
            <iyz>-5.9778e-36</iyz>
            <izz>0.0037033</izz>
          </inertia>
        </inertial>
        <collision name='FR_Wheel_collision'>
          <pose>0 0 0 0 -0 0</pose>
          <geometry>
            <mesh>
              <scale>1 1 1</scale>
              <uri>/home/arc/Documents/GitHub/IGVC-Robot/GazeboR1/WorkingRobot/Wheel_Detailed.STL</uri>
            </mesh>
          </geometry>
          <max_contacts>10</max_contacts>
          <surface>
            <contact>
              <ode/>
            </contact>
            <bounce/>
            <friction>
              <torsional>
                <ode/>
              </torsional>
              <ode/>
            </friction>
          </surface>
        </collision>
        <visual name='FR_Wheel_visual'>
          <pose>0 0 0 0 -0 0</pose>
          <geometry>
            <mesh>
              <scale>1 1 1</scale>
              <uri>/home/arc/Documents/GitHub/IGVC-Robot/GazeboR1/WorkingRobot/Wheel_Detailed.STL</uri>
            </mesh>
          </geometry>
        </visual>
        <self_collide>0</self_collide>
        <enable_wind>0</enable_wind>
        <kinematic>0</kinematic>
      </link>
      <pose>-0.275143 -0.736284 0 0 -0 0</pose>
    </model>
    <state world_name='default'>
      <sim_time>79 483000000</sim_time>
      <real_time>139 112989231</real_time>
      <wall_time>1663873466 679920826</wall_time>
      <iterations>79483</iterations>
      <model name='HitBox'>
        <pose>-0.272639 -0.610621 -0.000485 2e-06 0.000792 0.003625</pose>
        <scale>1 1 1</scale>
        <link name='BL_Wheel'>
          <pose>-0.285883 -0.504469 0.099094 -0.314241 -0.000792 -3.13797</pose>
          <velocity>7.4e-05 0.046826 -0.000338 -0.640179 -0.007261 0.001144</velocity>
          <acceleration>-0.066318 -0.001011 6.11361 0.001892 -0.358573 -0.004244</acceleration>
          <wrench>-0.066318 -0.001011 6.11361 0 -0 0</wrench>
        </link>
        <link name='BR_Wheel'>
          <pose>0.400379 -0.501981 0.098553 0.297286 0.00082 0.003625</pose>
          <velocity>-0.00011 0.047266 0.003521 -0.479877 -0.001297 0.001016</velocity>
          <acceleration>-0.444268 -0.004541 7.09843 3.1007 -1.26632 3.13334</acceleration>
          <wrench>-0.444268 -0.004541 7.09843 0 -0 0</wrench>
        </link>
        <link name='FL_Wheel'>
          <pose>-0.288428 0.197527 0.099095 -0.314343 -0.000792 -3.13797</pose>
          <velocity>-0.00037 0.046824 -0.000297 -0.638125 -0.007238 0.001143</velocity>
          <acceleration>-0.060128 -0.000892 6.06899 0.001546 -0.319913 -0.004095</acceleration>
          <wrench>-0.060128 -0.000892 6.06899 0 -0 0</wrench>
        </link>
        <link name='FR_Wheel'>
          <pose>0.397835 0.200015 0.098553 0.297846 0.000802 0.003625</pose>
          <velocity>-0.000449 0.047262 0.003069 -0.479835 -0.004632 0.001018</velocity>
          <acceleration>-0.217856 -0.004437 6.30255 -3.1352 -0.707554 3.13825</acceleration>
          <wrench>-0.217856 -0.004437 6.30255 0 -0 0</wrench>
        </link>
        <link name='Frame'>
          <pose>-0.272639 -0.610621 -0.000485 2e-06 0.000792 0.003625</pose>
          <velocity>0.000634 0.046844 -0.000285 9.5e-05 -0.00494 0.000636</velocity>
          <acceleration>-0.095039 -0.001384 6.2252 -0.011074 -0.358445 -0.003926</acceleration>
          <wrench>-3.38264 -0.049267 221.567 0 -0 0</wrench>
        </link>
      </model>
      <model name='my_ground_plane'>
        <pose>-0.007726 -0.007727 0 0 -0 0</pose>
        <scale>1 1 1</scale>
        <link name='link'>
          <pose>-0.007726 -0.007727 0 0 -0 0</pose>
          <velocity>0 0 0 0 -0 0</velocity>
          <acceleration>0 0 0 0 -0 0</acceleration>
          <wrench>0 0 0 0 -0 0</wrench>
        </link>
      </model>
      <light name='sun'>
        <pose>0 0 10 0 -0 0</pose>
      </light>
    </state>
    <gui fullscreen='0'>
      <camera name='user_camera'>
        <pose>-3.15307 -5.77282 2.06552 0 0.323643 0.972195</pose>
        <view_controller>orbit</view_controller>
        <projection_type>perspective</projection_type>
      </camera>
    </gui>
  </world>
</sdf>
