<?xml version="1.0" encoding="utf-8"?>
<!-- This URDF was automatically created by SolidWorks to URDF Exporter! Originally created by Stephen Brawner (brawner@gmail.com) 
     Commit Version: 1.6.0-4-g7f85cfe  Build Version: 1.6.7995.38578
     For more information, please see http://wiki.ros.org/sw_urdf_exporter -->
<robot
  name="PreliminaryDesignR1">
  <link
    name="Frame">
    <inertial>
      <origin
        xyz="-0.22688 0.2861 0.79829"
        rpy="0 0 0" />
      <mass
        value="45" />
      <inertia
        ixx="0.11061"
        ixy="-2.2706E-17"
        ixz="-1.1532E-16"
        iyy="0.12283"
        iyz="-3.4431E-17"
        izz="0.030355" />
    </inertial>
    <visual>
      <origin
        xyz="0 0 0"
        rpy="0 0 0" />
      <geometry>
        <mesh
          filename="package://PreliminaryDesignR1/meshes/Frame.STL" />
      </geometry>
      <material
        name="">
        <color
          rgba="0.95686 0.95686 0.95686 1" />
      </material>
    </visual>
    <collision>
      <origin
        xyz="0 0 0"
        rpy="0 0 0" />
      <geometry>
        <mesh
          filename="package://PreliminaryDesignR1/meshes/Frame.STL" />
      </geometry>
    </collision>
  </link>
  <link
    name="BR_Tire">
    <inertial>
      <origin
        xyz="0.019421 0.0088099 0.013964"
        rpy="0 0 0" />
      <mass
        value="0.48343" />
      <inertia
        ixx="0.0014473"
        ixy="7.448E-11"
        ixz="1.0731E-10"
        iyy="0.0014481"
        iyz="1.1416E-07"
        izz="0.0026705" />
    </inertial>
    <visual>
      <origin
        xyz="0 0 0"
        rpy="0 0 0" />
      <geometry>
        <mesh
          filename="package://PreliminaryDesignR1/meshes/BR_Tire.STL" />
      </geometry>
      <material
        name="">
        <color
          rgba="0.69804 0.69804 0.69804 1" />
      </material>
    </visual>
    <collision>
      <origin
        xyz="0 0 0"
        rpy="0 0 0" />
      <geometry>
        <mesh
          filename="package://PreliminaryDesignR1/meshes/BR_Tire.STL" />
      </geometry>
    </collision>
  </link>
  <joint
    name="BR_Axel"
    type="continuous">
    <origin
      xyz="0.15395 -1.1487 0.14743"
      rpy="-1.5708 1.1702 1.5708" />
    <parent
      link="Frame" />
    <child
      link="BR_Tire" />
    <axis
      xyz="0 0 0" />
  </joint>
  <link
    name="FR_Tire">
    <inertial>
      <origin
        xyz="0.019421 0.0088099 -0.013964"
        rpy="0 0 0" />
      <mass
        value="0.48343" />
      <inertia
        ixx="0.0014473"
        ixy="7.7958E-11"
        ixz="1.0321E-10"
        iyy="0.0014481"
        iyz="-1.1418E-07"
        izz="0.0026705" />
    </inertial>
    <visual>
      <origin
        xyz="0 0 0"
        rpy="0 0 0" />
      <geometry>
        <mesh
          filename="package://PreliminaryDesignR1/meshes/FR_Tire.STL" />
      </geometry>
      <material
        name="">
        <color
          rgba="0.69804 0.69804 0.69804 1" />
      </material>
    </visual>
    <collision>
      <origin
        xyz="0 0 0"
        rpy="0 0 0" />
      <geometry>
        <mesh
          filename="package://PreliminaryDesignR1/meshes/FR_Tire.STL" />
      </geometry>
    </collision>
  </link>
  <joint
    name="FR_Axel"
    type="continuous">
    <origin
      xyz="0.15395 -0.4524 0.10532"
      rpy="1.5708 -0.89895 1.5708" />
    <parent
      link="Frame" />
    <child
      link="FR_Tire" />
    <axis
      xyz="0 0 0" />
  </joint>
  <link
    name="FL_Tire">
    <inertial>
      <origin
        xyz="0.019421 0.0088099 0.013964"
        rpy="0 0 0" />
      <mass
        value="0.48343" />
      <inertia
        ixx="0.0014473"
        ixy="7.448E-11"
        ixz="1.0731E-10"
        iyy="0.0014481"
        iyz="1.1416E-07"
        izz="0.0026705" />
    </inertial>
    <visual>
      <origin
        xyz="0 0 0"
        rpy="0 0 0" />
      <geometry>
        <mesh
          filename="package://PreliminaryDesignR1/meshes/FL_Tire.STL" />
      </geometry>
      <material
        name="">
        <color
          rgba="0.69804 0.69804 0.69804 1" />
      </material>
    </visual>
    <collision>
      <origin
        xyz="0 0 0"
        rpy="0 0 0" />
      <geometry>
        <mesh
          filename="package://PreliminaryDesignR1/meshes/FL_Tire.STL" />
      </geometry>
    </collision>
  </link>
  <joint
    name="FL_Axel"
    type="continuous">
    <origin
      xyz="-0.60772 -0.4524 0.10532"
      rpy="1.5708 -0.89895 1.5708" />
    <parent
      link="Frame" />
    <child
      link="FL_Tire" />
    <axis
      xyz="0 0 0" />
  </joint>
  <link
    name="BL_Tire">
    <inertial>
      <origin
        xyz="0.019421 0.0088099 -0.013964"
        rpy="0 0 0" />
      <mass
        value="0.48343" />
      <inertia
        ixx="0.0014473"
        ixy="7.7958E-11"
        ixz="1.0321E-10"
        iyy="0.0014481"
        iyz="-1.1418E-07"
        izz="0.0026705" />
    </inertial>
    <visual>
      <origin
        xyz="0 0 0"
        rpy="0 0 0" />
      <geometry>
        <mesh
          filename="package://PreliminaryDesignR1/meshes/BL_Tire.STL" />
      </geometry>
      <material
        name="">
        <color
          rgba="0.69804 0.69804 0.69804 1" />
      </material>
    </visual>
    <collision>
      <origin
        xyz="0 0 0"
        rpy="0 0 0" />
      <geometry>
        <mesh
          filename="package://PreliminaryDesignR1/meshes/BL_Tire.STL" />
      </geometry>
    </collision>
  </link>
  <joint
    name="BL_Axel"
    type="continuous">
    <origin
      xyz="-0.60772 -1.1487 0.14743"
      rpy="-1.5708 1.1702 1.5708" />
    <parent
      link="Frame" />
    <child
      link="BL_Tire" />
    <axis
      xyz="0 0 0" />
  </joint>
</robot>